<sdf version='1.6'>
  <model name='erlecopter'>
    <link name='party_1/instance_1/base_link'>
      <pose frame=''>0 0 0 0 -0 0</pose>
      <inertial>
        <pose frame=''>0 -0 -0 0 -0 0</pose>
        <mass>1.10001</mass>
        <inertia>
          <ixx>0.0347585</ixx>
          <ixy>4.28706e-09</ixy>
          <ixz>-1.55282e-08</ixz>
          <iyy>0.0458949</iyy>
          <iyz>3.77509e-09</iyz>
          <izz>0.0977004</izz>
        </inertia>
      </inertial>
      <collision name='party_1/instance_1/base_link_inertia_collision'>
        <pose frame=''>0 0 0 0 -0 0</pose>
        <geometry>
          <mesh>
            <scale>1 1 1</scale>
            <uri>model://rotors_description/meshes/erlecopter_test_2.dae</uri>
          </mesh>
        </geometry>
      </collision>
      <collision name='party_1/instance_1/base_link_fixed_joint_lump__guidance_link_1_collision_1'>
        <pose frame=''>0 0 -0.0373 3.14159 -0 0</pose>
        <geometry>
          <mesh>
            <scale>1 1 1</scale>
            <uri>file:///home/tbm/temp/test_models/models/guidance_2/meshes/untitled2.dae</uri>
          </mesh>
        </geometry>
        <surface>
          <contact>
            <ode/>
          </contact>
          <friction>
            <ode/>
          </friction>
        </surface>
      </collision>
      <visual name='party_1/instance_1/base_link_inertia_visual'>
        <pose frame=''>0 0 0 0 -0 0</pose>
        <geometry>
          <mesh>
            <scale>1 1 1</scale>
            <uri>model://rotors_description/meshes/erlecopter_test_2.dae</uri>
          </mesh>
        </geometry>
      </visual>
      <visual name='party_1/instance_1/base_link_fixed_joint_lump__guidance_link_1_visual_1'>
        <pose frame=''>0 0 -0.0373 3.14159 -0 0</pose>
        <geometry>
          <mesh>
            <scale>1 1 1</scale>
            <uri>file:///home/tbm/temp/test_models/models/guidance_2/meshes/untitled2.dae</uri>
          </mesh>
        </geometry>
        <material>
          <script>
            <uri>__default__</uri>
            <name>__default__</name>
          </script>
        </material>
      </visual>
      <gravity>1</gravity>
      <velocity_decay/>
      <self_collide>0</self_collide>
      <sensor name='stereo_camera_1' type='multicamera'>
        <update_rate>50</update_rate>
        <camera name='left'>
          <pose frame=''>0.1035 -0.0765 -0.0553 3.14159 -0 0</pose>
          <horizontal_fov>1.39626</horizontal_fov>
          <image>
            <width>800</width>
            <height>800</height>
          </image>
          <clip>
            <near>0.002</near>
            <far>3000</far>
          </clip>
        </camera>
        <camera name='right'>
          <pose frame=''>0.1035 0.0755 -0.0553 3.14159 -0 0</pose>
          <horizontal_fov>1.39626</horizontal_fov>
          <image>
            <width>800</width>
            <height>800</height>
          </image>
          <clip>
            <near>0.002</near>
            <far>3000</far>
          </clip>
        </camera>
        <plugin name='stereo_camera_controller_1' filename='libgazebo_ros_multicamera.so'>
          <alwaysOn>true</alwaysOn>
          <updateRate>0.0</updateRate>
          <robotNamespace>party_1/instance_1</robotNamespace>
          <cameraName>guidance_camera_1</cameraName>
          <imageTopicName>image_raw</imageTopicName>
          <cameraInfoTopicName>camera_info_1</cameraInfoTopicName>
          <frameName>left_camera_optical_frame</frameName>
          <hackBaseline>0.07</hackBaseline>
          <distortionK1>0.0</distortionK1>
          <distortionK2>0.0</distortionK2>
          <distortionK3>0.0</distortionK3>
          <distortionT1>0.0</distortionT1>
          <distortionT2>0.0</distortionT2>
        </plugin>
        <pose frame=''>0 0 -0.0373 3.14159 -0 0</pose>
      </sensor>
      <sensor name='stereo_camera_2' type='multicamera'>
        <update_rate>50</update_rate>
        <camera name='left'>
          <pose frame=''>-0.1035 -0.0765 -0.0553 3.14159 -0 -3.14159</pose>
          <horizontal_fov>1.39626</horizontal_fov>
          <image>
            <width>800</width>
            <height>800</height>
          </image>
          <clip>
            <near>0.002</near>
            <far>3000</far>
          </clip>
        </camera>
        <camera name='right'>
          <pose frame=''>-0.1035 0.0755 -0.0553 3.14159 -0 -3.14159</pose>
          <horizontal_fov>1.39626</horizontal_fov>
          <image>
            <width>800</width>
            <height>800</height>
          </image>
          <clip>
            <near>0.002</near>
            <far>3000</far>
          </clip>
        </camera>
        <plugin name='stereo_camera_controller_2' filename='libgazebo_ros_multicamera.so'>
          <alwaysOn>true</alwaysOn>
          <updateRate>0.0</updateRate>
          <robotNamespace>party_1/instance_1</robotNamespace>
          <cameraName>guidance_camera_2</cameraName>
          <imageTopicName>image_raw</imageTopicName>
          <cameraInfoTopicName>camera_info_2</cameraInfoTopicName>
          <frameName>left_camera_optical_frame</frameName>
          <hackBaseline>0.07</hackBaseline>
          <distortionK1>0.0</distortionK1>
          <distortionK2>0.0</distortionK2>
          <distortionK3>0.0</distortionK3>
          <distortionT1>0.0</distortionT1>
          <distortionT2>0.0</distortionT2>
        </plugin>
        <pose frame=''>0 0 -0.0373 3.14159 -0 0</pose>
      </sensor>
      <sensor name='stereo_camera_3' type='multicamera'>
        <update_rate>50</update_rate>
        <camera name='left'>
          <pose frame=''>0.0005 0.028 -0.0553 3.14159 -0 1.5708</pose>
          <horizontal_fov>1.39626</horizontal_fov>
          <image>
            <width>800</width>
            <height>800</height>
          </image>
          <clip>
            <near>0.002</near>
            <far>3000</far>
          </clip>
        </camera>
        <camera name='right'>
          <pose frame=''>0.0005 0.18 -0.0553 3.14159 -0 1.5708</pose>
          <horizontal_fov>1.39626</horizontal_fov>
          <image>
            <width>800</width>
            <height>800</height>
          </image>
          <clip>
            <near>0.002</near>
            <far>3000</far>
          </clip>
        </camera>
        <plugin name='stereo_camera_controller_3' filename='libgazebo_ros_multicamera.so'>
          <alwaysOn>true</alwaysOn>
          <updateRate>0.0</updateRate>
          <robotNamespace>party_1/instance_1</robotNamespace>
          <cameraName>guidance_camera_3</cameraName>
          <imageTopicName>image_raw</imageTopicName>
          <cameraInfoTopicName>camera_info_3</cameraInfoTopicName>
          <frameName>left_camera_optical_frame</frameName>
          <hackBaseline>0.07</hackBaseline>
          <distortionK1>0.0</distortionK1>
          <distortionK2>0.0</distortionK2>
          <distortionK3>0.0</distortionK3>
          <distortionT1>0.0</distortionT1>
          <distortionT2>0.0</distortionT2>
        </plugin>
        <pose frame=''>0 0 -0.0373 3.14159 -0 0</pose>
      </sensor>
      <sensor name='stereo_camera_4' type='multicamera'>
        <update_rate>50</update_rate>
        <camera name='left'>
          <pose frame=''>0.0005 -0.18 -0.0553 3.14159 0 -1.5708</pose>
          <horizontal_fov>1.39626</horizontal_fov>
          <image>
            <width>800</width>
            <height>800</height>
          </image>
          <clip>
            <near>0.002</near>
            <far>3000</far>
          </clip>
        </camera>
        <camera name='right'>
          <pose frame=''>0.0005 -0.028 -0.0553 3.14159 0 -1.5708</pose>
          <horizontal_fov>1.39626</horizontal_fov>
          <image>
            <width>800</width>
            <height>800</height>
          </image>
          <clip>
            <near>0.002</near>
            <far>3000</far>
          </clip>
        </camera>
        <plugin name='stereo_camera_controller_4' filename='libgazebo_ros_multicamera.so'>
          <alwaysOn>true</alwaysOn>
          <updateRate>0.0</updateRate>
          <robotNamespace>party_1/instance_1</robotNamespace>
          <cameraName>guidance_camera_4</cameraName>
          <imageTopicName>image_raw</imageTopicName>
          <cameraInfoTopicName>camera_info_4</cameraInfoTopicName>
          <frameName>left_camera_optical_frame</frameName>
          <hackBaseline>0.07</hackBaseline>
          <distortionK1>0.0</distortionK1>
          <distortionK2>0.0</distortionK2>
          <distortionK3>0.0</distortionK3>
          <distortionT1>0.0</distortionT1>
          <distortionT2>0.0</distortionT2>
        </plugin>
        <pose frame=''>0 0 -0.0373 3.14159 -0 0</pose>
      </sensor>
      <sensor name='stereo_camera_5' type='multicamera'>
        <update_rate>50</update_rate>
        <camera name='left'>
          <pose frame=''>-0.02 0.0755 0.0888 3.14159 -1.5708 -0</pose>
          <horizontal_fov>1.39626</horizontal_fov>
          <image>
            <width>800</width>
            <height>800</height>
          </image>
          <clip>
            <near>0.002</near>
            <far>3000</far>
          </clip>
        </camera>
        <camera name='right'>
          <pose frame=''>-0.02 0.0765 0.0888 3.14159 -1.5708 -0</pose>
          <horizontal_fov>1.39626</horizontal_fov>
          <image>
            <width>800</width>
            <height>800</height>
          </image>
          <clip>
            <near>0.002</near>
            <far>3000</far>
          </clip>
        </camera>
        <plugin name='stereo_camera_controller_5' filename='libgazebo_ros_multicamera.so'>
          <alwaysOn>true</alwaysOn>
          <updateRate>0.0</updateRate>
          <robotNamespace>party_1/instance_1</robotNamespace>
          <cameraName>guidance_camera_5</cameraName>
          <imageTopicName>image_raw</imageTopicName>
          <cameraInfoTopicName>camera_info_5</cameraInfoTopicName>
          <frameName>left_camera_optical_frame</frameName>
          <hackBaseline>0.07</hackBaseline>
          <distortionK1>0.0</distortionK1>
          <distortionK2>0.0</distortionK2>
          <distortionK3>0.0</distortionK3>
          <distortionT1>0.0</distortionT1>
          <distortionT2>0.0</distortionT2>
        </plugin>
        <pose frame=''>0 0 -0.0373 3.14159 -0 0</pose>
      </sensor>
    </link>
    <link name='lidar_link_1'>
      <pose frame=''>-0.04 0 0.065 0.523599 -0 0</pose>
      <inertial>
        <pose frame=''>0 0 0 0 -0 0</pose>
        <mass>1e-05</mass>
        <inertia>
          <ixx>1e-09</ixx>
          <ixy>0</ixy>
          <ixz>0</ixz>
          <iyy>1e-10</iyy>
          <iyz>0</iyz>
          <izz>1e-11</izz>
        </inertia>
      </inertial>
      <collision name='lidar_link_1_collision'>
        <pose frame=''>0 0 0 0 -0 0</pose>
        <geometry>
          <cylinder>
            <length>0.03</length>
            <radius>0.035</radius>
          </cylinder>
        </geometry>
        <surface>
          <contact>
            <ode/>
          </contact>
          <friction>
            <ode/>
          </friction>
        </surface>
      </collision>
      <visual name='lidar_link_1_visual'>
        <pose frame=''>0 0 0 0 -0 0</pose>
        <geometry>
          <cylinder>
            <length>0.03</length>
            <radius>0.035</radius>
          </cylinder>
        </geometry>
        <material>
          <script>
            <uri>__default__</uri>
            <name>__default__</name>
          </script>
        </material>
      </visual>
      <gravity>1</gravity>
      <velocity_decay/>
      <self_collide>0</self_collide>
      <sensor name='self_made_lidar' type='ray'>
        <always_on>1</always_on>
        <visualize>1</visualize>
        <update_rate>40</update_rate>
        <ray>
          <scan>
            <horizontal>
              <samples>720</samples>
              <resolution>1</resolution>
              <min_angle>0</min_angle>
              <max_angle>1.5708</max_angle>
            </horizontal>
          </scan>
          <range>
            <min>0.1</min>
            <max>10</max>
            <resolution>0.01</resolution>
          </range>
        </ray>
        <plugin name='self_made_lidar_controller_1' filename='libgazebo_ros_laser.so'>
          <robotNamespace>party_1/instance_1</robotNamespace>
          <topicName>laser/scan/1</topicName>
          <frameName>lidar_link_1</frameName>
        </plugin>
      </sensor>
    </link>
    <joint name='erlecopter_lidar_joint_1' type='revolute'>
      <child>lidar_link_1</child>
      <parent>party_1/instance_1/base_link</parent>
      <axis>
        <xyz>0 -0 1</xyz>
        <limit>
          <lower>-1e+16</lower>
          <upper>1e+16</upper>
        </limit>
        <dynamics>
          <spring_reference>0</spring_reference>
          <spring_stiffness>0</spring_stiffness>
        </dynamics>
        <use_parent_model_frame>1</use_parent_model_frame>
      </axis>
    </joint>
    <link name='party_1/instance_1/rotor_0'>
      <pose frame=''>0.141 -0.141 0.03 0 -0 0</pose>
      <inertial>
        <pose frame=''>0 0 0 0 -0 0</pose>
        <mass>0.005</mass>
        <inertia>
          <ixx>9.75e-07</ixx>
          <ixy>0</ixy>
          <ixz>0</ixz>
          <iyy>0.000240038</iyy>
          <iyz>0</iyz>
          <izz>0.000240937</izz>
        </inertia>
      </inertial>
      <collision name='party_1/instance_1/rotor_0_collision'>
        <pose frame=''>0 0 0 0 -0 0</pose>
        <geometry>
          <cylinder>
            <length>0.005</length>
            <radius>0.12</radius>
          </cylinder>
        </geometry>
        <surface>
          <contact>
            <ode/>
          </contact>
          <friction>
            <ode/>
          </friction>
        </surface>
      </collision>
      <visual name='party_1/instance_1/rotor_0_visual'>
        <pose frame=''>0 0 0 0 -0 0</pose>
        <geometry>
          <mesh>
            <scale>1 1 1</scale>
            <uri>model://rotors_description/meshes/erlecopter_propeller_ccw.dae</uri>
          </mesh>
        </geometry>
        <material>
          <script>
            <name>Gazebo/Yellow</name>
            <uri>file://media/materials/scripts/gazebo.material</uri>
          </script>
        </material>
      </visual>
      <gravity>1</gravity>
      <velocity_decay/>
      <self_collide>0</self_collide>
    </link>
    <joint name='party_1/instance_1/rotor_0_joint' type='revolute'>
      <child>party_1/instance_1/rotor_0</child>
      <parent>party_1/instance_1/base_link</parent>
      <axis>
        <xyz>0 0 1</xyz>
        <limit>
          <lower>-1e+16</lower>
          <upper>1e+16</upper>
        </limit>
        <dynamics>
          <spring_reference>0</spring_reference>
          <spring_stiffness>0</spring_stiffness>
        </dynamics>
        <use_parent_model_frame>1</use_parent_model_frame>
      </axis>
    </joint>
    <link name='party_1/instance_1/rotor_1'>
      <pose frame=''>-0.141 0.141 0.03 0 -0 0</pose>
      <inertial>
        <pose frame=''>0 0 0 0 -0 0</pose>
        <mass>0.005</mass>
        <inertia>
          <ixx>9.75e-07</ixx>
          <ixy>0</ixy>
          <ixz>0</ixz>
          <iyy>0.000240038</iyy>
          <iyz>0</iyz>
          <izz>0.000240937</izz>
        </inertia>
      </inertial>
      <collision name='party_1/instance_1/rotor_1_collision'>
        <pose frame=''>0 0 0 0 -0 0</pose>
        <geometry>
          <cylinder>
            <length>0.005</length>
            <radius>0.12</radius>
          </cylinder>
        </geometry>
        <surface>
          <contact>
            <ode/>
          </contact>
          <friction>
            <ode/>
          </friction>
        </surface>
      </collision>
      <visual name='party_1/instance_1/rotor_1_visual'>
        <pose frame=''>0 0 0 0 -0 0</pose>
        <geometry>
          <mesh>
            <scale>1 1 1</scale>
            <uri>model://rotors_description/meshes/erlecopter_propeller_ccw.dae</uri>
          </mesh>
        </geometry>
        <material>
          <script>
            <name>Gazebo/Black</name>
            <uri>file://media/materials/scripts/gazebo.material</uri>
          </script>
        </material>
      </visual>
      <gravity>1</gravity>
      <velocity_decay/>
      <self_collide>0</self_collide>
    </link>
    <joint name='party_1/instance_1/rotor_1_joint' type='revolute'>
      <child>party_1/instance_1/rotor_1</child>
      <parent>party_1/instance_1/base_link</parent>
      <axis>
        <xyz>0 0 1</xyz>
        <limit>
          <lower>-1e+16</lower>
          <upper>1e+16</upper>
        </limit>
        <dynamics>
          <spring_reference>0</spring_reference>
          <spring_stiffness>0</spring_stiffness>
        </dynamics>
        <use_parent_model_frame>1</use_parent_model_frame>
      </axis>
    </joint>
    <link name='party_1/instance_1/rotor_2'>
      <pose frame=''>0.141 0.141 0.03 0 -0 0</pose>
      <inertial>
        <pose frame=''>0 0 0 0 -0 0</pose>
        <mass>0.005</mass>
        <inertia>
          <ixx>9.75e-07</ixx>
          <ixy>0</ixy>
          <ixz>0</ixz>
          <iyy>0.000240038</iyy>
          <iyz>0</iyz>
          <izz>0.000240937</izz>
        </inertia>
      </inertial>
      <collision name='party_1/instance_1/rotor_2_collision'>
        <pose frame=''>0 0 0 0 -0 0</pose>
        <geometry>
          <cylinder>
            <length>0.005</length>
            <radius>0.12</radius>
          </cylinder>
        </geometry>
        <surface>
          <contact>
            <ode/>
          </contact>
          <friction>
            <ode/>
          </friction>
        </surface>
      </collision>
      <visual name='party_1/instance_1/rotor_2_visual'>
        <pose frame=''>0 0 0 0 -0 0</pose>
        <geometry>
          <mesh>
            <scale>1 1 1</scale>
            <uri>model://rotors_description/meshes/erlecopter_propeller_cw.dae</uri>
          </mesh>
        </geometry>
        <material>
          <script>
            <name>Gazebo/Yellow</name>
            <uri>file://media/materials/scripts/gazebo.material</uri>
          </script>
        </material>
      </visual>
      <gravity>1</gravity>
      <velocity_decay/>
      <self_collide>0</self_collide>
    </link>
    <joint name='party_1/instance_1/rotor_2_joint' type='revolute'>
      <child>party_1/instance_1/rotor_2</child>
      <parent>party_1/instance_1/base_link</parent>
      <axis>
        <xyz>0 0 1</xyz>
        <limit>
          <lower>-1e+16</lower>
          <upper>1e+16</upper>
        </limit>
        <dynamics>
          <spring_reference>0</spring_reference>
          <spring_stiffness>0</spring_stiffness>
        </dynamics>
        <use_parent_model_frame>1</use_parent_model_frame>
      </axis>
    </joint>
    <link name='party_1/instance_1/rotor_3'>
      <pose frame=''>-0.141 -0.141 0.03 0 -0 0</pose>
      <inertial>
        <pose frame=''>0 0 0 0 -0 0</pose>
        <mass>0.005</mass>
        <inertia>
          <ixx>9.75e-07</ixx>
          <ixy>0</ixy>
          <ixz>0</ixz>
          <iyy>0.000240038</iyy>
          <iyz>0</iyz>
          <izz>0.000240937</izz>
        </inertia>
      </inertial>
      <collision name='party_1/instance_1/rotor_3_collision'>
        <pose frame=''>0 0 0 0 -0 0</pose>
        <geometry>
          <cylinder>
            <length>0.005</length>
            <radius>0.12</radius>
          </cylinder>
        </geometry>
        <surface>
          <contact>
            <ode/>
          </contact>
          <friction>
            <ode/>
          </friction>
        </surface>
      </collision>
      <visual name='party_1/instance_1/rotor_3_visual'>
        <pose frame=''>0 0 0 0 -0 0</pose>
        <geometry>
          <mesh>
            <scale>1 1 1</scale>
            <uri>model://rotors_description/meshes/erlecopter_propeller_cw.dae</uri>
          </mesh>
        </geometry>
        <material>
          <script>
            <name>Gazebo/Black</name>
            <uri>file://media/materials/scripts/gazebo.material</uri>
          </script>
        </material>
      </visual>
      <gravity>1</gravity>
      <velocity_decay/>
      <self_collide>0</self_collide>
    </link>
    <joint name='party_1/instance_1/rotor_3_joint' type='revolute'>
      <child>party_1/instance_1/rotor_3</child>
      <parent>party_1/instance_1/base_link</parent>
      <axis>
        <xyz>0 0 1</xyz>
        <limit>
          <lower>-1e+16</lower>
          <upper>1e+16</upper>
        </limit>
        <dynamics>
          <spring_reference>0</spring_reference>
          <spring_stiffness>0</spring_stiffness>
        </dynamics>
        <use_parent_model_frame>1</use_parent_model_frame>
      </axis>
    </joint>
    <plugin name='multirotor_base_plugin' filename='librotors_gazebo_multirotor_base_plugin.so'>
      <robotNamespace>party_1/instance_1</robotNamespace>
      <linkName>party_1/instance_1/base_link</linkName>
      <rotorVelocitySlowdownSim>10</rotorVelocitySlowdownSim>
    </plugin>
    <plugin name='party_1/instance_1_front_right_motor_model' filename='librotors_gazebo_motor_model.so'>
      <robotNamespace>party_1/instance_1</robotNamespace>
      <jointName>party_1/instance_1/rotor_0_joint</jointName>
      <linkName>party_1/instance_1/rotor_0</linkName>
      <turningDirection>ccw</turningDirection>
      <timeConstantUp>0.0125</timeConstantUp>
      <timeConstantDown>0.025</timeConstantDown>
      <maxRotVelocity>838</maxRotVelocity>
      <motorConstant>8.54858e-06</motorConstant>
      <momentConstant>0.016</momentConstant>
      <commandSubTopic>gazebo/command/motor_speed</commandSubTopic>
      <motorNumber>0</motorNumber>
      <rotorDragCoefficient>8.06428e-05</rotorDragCoefficient>
      <rollingMomentCoefficient>1e-06</rollingMomentCoefficient>
      <motorSpeedPubTopic>motor_speed/0</motorSpeedPubTopic>
      <rotorVelocitySlowdownSim>10</rotorVelocitySlowdownSim>
    </plugin>
    <plugin name='party_1/instance_1_back_left_motor_model' filename='librotors_gazebo_motor_model.so'>
      <robotNamespace>party_1/instance_1</robotNamespace>
      <jointName>party_1/instance_1/rotor_1_joint</jointName>
      <linkName>party_1/instance_1/rotor_1</linkName>
      <turningDirection>ccw</turningDirection>
      <timeConstantUp>0.0125</timeConstantUp>
      <timeConstantDown>0.025</timeConstantDown>
      <maxRotVelocity>838</maxRotVelocity>
      <motorConstant>8.54858e-06</motorConstant>
      <momentConstant>0.016</momentConstant>
      <commandSubTopic>gazebo/command/motor_speed</commandSubTopic>
      <motorNumber>1</motorNumber>
      <rotorDragCoefficient>8.06428e-05</rotorDragCoefficient>
      <rollingMomentCoefficient>1e-06</rollingMomentCoefficient>
      <motorSpeedPubTopic>motor_speed/1</motorSpeedPubTopic>
      <rotorVelocitySlowdownSim>10</rotorVelocitySlowdownSim>
    </plugin>
    <plugin name='party_1/instance_1_front_left_motor_model' filename='librotors_gazebo_motor_model.so'>
      <robotNamespace>party_1/instance_1</robotNamespace>
      <jointName>party_1/instance_1/rotor_2_joint</jointName>
      <linkName>party_1/instance_1/rotor_2</linkName>
      <turningDirection>cw</turningDirection>
      <timeConstantUp>0.0125</timeConstantUp>
      <timeConstantDown>0.025</timeConstantDown>
      <maxRotVelocity>838</maxRotVelocity>
      <motorConstant>8.54858e-06</motorConstant>
      <momentConstant>0.016</momentConstant>
      <commandSubTopic>gazebo/command/motor_speed</commandSubTopic>
      <motorNumber>2</motorNumber>
      <rotorDragCoefficient>8.06428e-05</rotorDragCoefficient>
      <rollingMomentCoefficient>1e-06</rollingMomentCoefficient>
      <motorSpeedPubTopic>motor_speed/2</motorSpeedPubTopic>
      <rotorVelocitySlowdownSim>10</rotorVelocitySlowdownSim>
    </plugin>
    <plugin name='party_1/instance_1_back_right_motor_model' filename='librotors_gazebo_motor_model.so'>
      <robotNamespace>party_1/instance_1</robotNamespace>
      <jointName>party_1/instance_1/rotor_3_joint</jointName>
      <linkName>party_1/instance_1/rotor_3</linkName>
      <turningDirection>cw</turningDirection>
      <timeConstantUp>0.0125</timeConstantUp>
      <timeConstantDown>0.025</timeConstantDown>
      <maxRotVelocity>838</maxRotVelocity>
      <motorConstant>8.54858e-06</motorConstant>
      <momentConstant>0.016</momentConstant>
      <commandSubTopic>gazebo/command/motor_speed</commandSubTopic>
      <motorNumber>3</motorNumber>
      <rotorDragCoefficient>8.06428e-05</rotorDragCoefficient>
      <rollingMomentCoefficient>1e-06</rollingMomentCoefficient>
      <motorSpeedPubTopic>motor_speed/3</motorSpeedPubTopic>
      <rotorVelocitySlowdownSim>10</rotorVelocitySlowdownSim>
    </plugin>
    <static>0</static>
    <plugin name='lidar_test_plugin_1' filename='liblidar_test_plugin_2.so'>
      <jointName>erlecopter_lidar_joint_1</jointName>
    </plugin>
  </model>
</sdf>
