<?xml version="1.0" ?>
<!-- =================================================================================== -->
<!-- |    This document was autogenerated by xacro from erlecopter_lidar.xacro         | -->
<!-- |    EDITING THIS FILE BY HAND IS NOT RECOMMENDED                                 | -->
<!-- =================================================================================== -->
<robot xmlns:xacro="http://www.ros.org/xacro">
  <link name="lidar_link_4">
    <inertial>
      <mass value="0.1"/>
      <inertia ixx="0.1" ixy="0.0" ixz="0.0" iyy="0.1" iyz="0.0" izz="0.1"/>
    </inertial>
    <collision>
      <geometry>
        <cylinder length="0.05" radius="0.05"/>
      </geometry>
    </collision>
    <visual>
      <geometry>
        <cylinder length="0.05" radius="0.05"/>
      </geometry>
    </visual>
  </link>
  <gazebo reference="lidar_link_4">
    <sensor name="self_made_lidar" type="ray">
      <always_on>true</always_on>
      <visualize>true</visualize>
      <update_rate>40</update_rate>
      <ray>
        <scan>
          <horizontal>
            <samples>720</samples>
            <resolution>1</resolution>
            <min_angle>0</min_angle>
            <max_angle>1.5707963</max_angle>
          </horizontal>
        </scan>
        <range>
          <min>0.10</min>
          <max>10.0</max>
          <resolution>0.01</resolution>
        </range>
      </ray>
      <plugin filename="libgazebo_ros_laser.so" name="self_made_lidar_controller_4">
        <topicName>laser/scan/4</topicName>
        <frameName>lidar_link_4</frameName>
      </plugin>
    </sensor>
  </gazebo>
  <joint name="erlecopter_lidar_joint_4" type="continuous">
    <origin rpy="0 0 0" xyz="0 0 0"/>
    <parent link="no_link"/>
    <child link="lidar_link_4"/>
    <axis xyz="0 0 0"/>
  </joint>
  <gazebo>
    <plugin filename="liblidar_test_plugin.so" name="lidar_test_plugin_4">
      <jointName>erlecopter_lidar_joint_4</jointName>
    </plugin>
  </gazebo>
  <gazebo>
    <plugin filename="libgazebo_ros_joint_state_publisher.so" name="joint_state_publisher_4">
      <jointName>erlecopter_lidar_joint_4</jointName>
    </plugin>
  </gazebo>
</robot>

